2020-06-17 11:51:10,583 ERROR: Exception on /send_glad_gift [POST] [in c:\users\harry\documents\oddsonglory\odds-on-glory\venv\lib\site-packages\flask\app.py:1891]
Traceback (most recent call last):
  File "c:\users\harry\documents\oddsonglory\odds-on-glory\venv\lib\site-packages\flask\app.py", line 2447, in wsgi_app
    response = self.full_dispatch_request()
  File "c:\users\harry\documents\oddsonglory\odds-on-glory\venv\lib\site-packages\flask\app.py", line 1952, in full_dispatch_request
    rv = self.handle_user_exception(e)
  File "c:\users\harry\documents\oddsonglory\odds-on-glory\venv\lib\site-packages\flask\app.py", line 1821, in handle_user_exception
    reraise(exc_type, exc_value, tb)
  File "c:\users\harry\documents\oddsonglory\odds-on-glory\venv\lib\site-packages\flask\_compat.py", line 39, in reraise
    raise value
  File "c:\users\harry\documents\oddsonglory\odds-on-glory\venv\lib\site-packages\flask\app.py", line 1950, in full_dispatch_request
    rv = self.dispatch_request()
  File "c:\users\harry\documents\oddsonglory\odds-on-glory\venv\lib\site-packages\flask\app.py", line 1936, in dispatch_request
    return self.view_functions[rule.endpoint](**req.view_args)
  File "C:\Users\Harry\Documents\OddsOnGlory\odds-on-glory\app\routes.py", line 110, in send_glad_gift
    game.sendGift(glad_id, gift, cost, current_user.id) ##gift var currently unused
  File "C:\Users\Harry\Documents\OddsOnGlory\odds-on-glory\app\game_files\game_handler.py", line 63, in sendGift
    sender.spendMoney(int(bet_value))
NameError: name 'bet_value' is not defined
2020-06-17 11:51:58,032 INFO: OddsOnGlory Game [in C:\Users\Harry\Documents\OddsOnGlory\odds-on-glory\app\__init__.py:52]
2020-06-17 11:53:49,603 INFO: OddsOnGlory Game [in C:\Users\Harry\Documents\OddsOnGlory\odds-on-glory\app\__init__.py:52]
2020-06-17 11:55:13,261 INFO: OddsOnGlory Game [in C:\Users\Harry\Documents\OddsOnGlory\odds-on-glory\app\__init__.py:52]
2020-06-17 11:58:02,871 INFO: OddsOnGlory Game [in C:\Users\Harry\Documents\OddsOnGlory\odds-on-glory\app\__init__.py:52]
2020-06-17 11:59:27,869 INFO: OddsOnGlory Game [in C:\Users\Harry\Documents\OddsOnGlory\odds-on-glory\app\__init__.py:52]
2020-06-17 12:02:47,917 INFO: OddsOnGlory Game [in C:\Users\Harry\Documents\OddsOnGlory\odds-on-glory\app\__init__.py:52]
2020-06-17 12:04:00,379 ERROR: Exception on /finish_game [POST] [in c:\users\harry\documents\oddsonglory\odds-on-glory\venv\lib\site-packages\flask\app.py:1891]
Traceback (most recent call last):
  File "c:\users\harry\documents\oddsonglory\odds-on-glory\venv\lib\site-packages\flask\app.py", line 2447, in wsgi_app
    response = self.full_dispatch_request()
  File "c:\users\harry\documents\oddsonglory\odds-on-glory\venv\lib\site-packages\flask\app.py", line 1952, in full_dispatch_request
    rv = self.handle_user_exception(e)
  File "c:\users\harry\documents\oddsonglory\odds-on-glory\venv\lib\site-packages\flask\app.py", line 1821, in handle_user_exception
    reraise(exc_type, exc_value, tb)
  File "c:\users\harry\documents\oddsonglory\odds-on-glory\venv\lib\site-packages\flask\_compat.py", line 39, in reraise
    raise value
  File "c:\users\harry\documents\oddsonglory\odds-on-glory\venv\lib\site-packages\flask\app.py", line 1950, in full_dispatch_request
    rv = self.dispatch_request()
  File "c:\users\harry\documents\oddsonglory\odds-on-glory\venv\lib\site-packages\flask\app.py", line 1936, in dispatch_request
    return self.view_functions[rule.endpoint](**req.view_args)
  File "C:\Users\Harry\Documents\OddsOnGlory\odds-on-glory\app\routes.py", line 118, in finish_game
    return (str(current_user.money))
  File "c:\users\harry\documents\oddsonglory\odds-on-glory\venv\lib\site-packages\werkzeug\local.py", line 347, in __getattr__
    return getattr(self._get_current_object(), name)
AttributeError: 'AnonymousUserMixin' object has no attribute 'money'
2020-06-17 12:04:00,383 ERROR: Exception on /finish_game [POST] [in c:\users\harry\documents\oddsonglory\odds-on-glory\venv\lib\site-packages\flask\app.py:1891]
Traceback (most recent call last):
  File "c:\users\harry\documents\oddsonglory\odds-on-glory\venv\lib\site-packages\flask\app.py", line 2447, in wsgi_app
    response = self.full_dispatch_request()
  File "c:\users\harry\documents\oddsonglory\odds-on-glory\venv\lib\site-packages\flask\app.py", line 1952, in full_dispatch_request
    rv = self.handle_user_exception(e)
  File "c:\users\harry\documents\oddsonglory\odds-on-glory\venv\lib\site-packages\flask\app.py", line 1821, in handle_user_exception
    reraise(exc_type, exc_value, tb)
  File "c:\users\harry\documents\oddsonglory\odds-on-glory\venv\lib\site-packages\flask\_compat.py", line 39, in reraise
    raise value
  File "c:\users\harry\documents\oddsonglory\odds-on-glory\venv\lib\site-packages\flask\app.py", line 1950, in full_dispatch_request
    rv = self.dispatch_request()
  File "c:\users\harry\documents\oddsonglory\odds-on-glory\venv\lib\site-packages\flask\app.py", line 1936, in dispatch_request
    return self.view_functions[rule.endpoint](**req.view_args)
  File "C:\Users\Harry\Documents\OddsOnGlory\odds-on-glory\app\routes.py", line 118, in finish_game
    return (str(current_user.money))
  File "c:\users\harry\documents\oddsonglory\odds-on-glory\venv\lib\site-packages\werkzeug\local.py", line 347, in __getattr__
    return getattr(self._get_current_object(), name)
AttributeError: 'AnonymousUserMixin' object has no attribute 'money'
2020-06-17 12:05:41,239 INFO: OddsOnGlory Game [in C:\Users\Harry\Documents\OddsOnGlory\odds-on-glory\app\__init__.py:52]
2020-06-17 12:06:08,858 INFO: OddsOnGlory Game [in C:\Users\Harry\Documents\OddsOnGlory\odds-on-glory\app\__init__.py:52]
2020-06-17 19:19:06,232 INFO: OddsOnGlory Game [in C:\Users\Harry\Documents\OddsOnGlory\odds-on-glory\app\__init__.py:52]
2020-06-17 19:19:41,083 ERROR: Exception on /browse_games [GET] [in c:\users\harry\documents\oddsonglory\odds-on-glory\venv\lib\site-packages\flask\app.py:1891]
Traceback (most recent call last):
  File "c:\users\harry\documents\oddsonglory\odds-on-glory\venv\lib\site-packages\flask\app.py", line 2447, in wsgi_app
    response = self.full_dispatch_request()
  File "c:\users\harry\documents\oddsonglory\odds-on-glory\venv\lib\site-packages\flask\app.py", line 1952, in full_dispatch_request
    rv = self.handle_user_exception(e)
  File "c:\users\harry\documents\oddsonglory\odds-on-glory\venv\lib\site-packages\flask\app.py", line 1821, in handle_user_exception
    reraise(exc_type, exc_value, tb)
  File "c:\users\harry\documents\oddsonglory\odds-on-glory\venv\lib\site-packages\flask\_compat.py", line 39, in reraise
    raise value
  File "c:\users\harry\documents\oddsonglory\odds-on-glory\venv\lib\site-packages\flask\app.py", line 1950, in full_dispatch_request
    rv = self.dispatch_request()
  File "c:\users\harry\documents\oddsonglory\odds-on-glory\venv\lib\site-packages\flask\app.py", line 1936, in dispatch_request
    return self.view_functions[rule.endpoint](**req.view_args)
  File "c:\users\harry\documents\oddsonglory\odds-on-glory\venv\lib\site-packages\flask_login\utils.py", line 272, in decorated_view
    return func(*args, **kwargs)
  File "C:\Users\Harry\Documents\OddsOnGlory\odds-on-glory\app\routes.py", line 209, in browse_games
    games = Tournament.query.all().paginate(page, app.config['POSTS_PER_PAGE'], False)
AttributeError: 'list' object has no attribute 'paginate'
2020-06-17 19:20:08,148 INFO: OddsOnGlory Game [in C:\Users\Harry\Documents\OddsOnGlory\odds-on-glory\app\__init__.py:52]
2020-06-17 19:20:39,171 INFO: OddsOnGlory Game [in C:\Users\Harry\Documents\OddsOnGlory\odds-on-glory\app\__init__.py:52]
2020-06-17 19:21:44,003 INFO: OddsOnGlory Game [in C:\Users\Harry\Documents\OddsOnGlory\odds-on-glory\app\__init__.py:52]
2020-06-17 19:22:56,091 ERROR: Exception on /finish_game [POST] [in c:\users\harry\documents\oddsonglory\odds-on-glory\venv\lib\site-packages\flask\app.py:1891]
Traceback (most recent call last):
  File "c:\users\harry\documents\oddsonglory\odds-on-glory\venv\lib\site-packages\flask\app.py", line 2447, in wsgi_app
    response = self.full_dispatch_request()
  File "c:\users\harry\documents\oddsonglory\odds-on-glory\venv\lib\site-packages\flask\app.py", line 1952, in full_dispatch_request
    rv = self.handle_user_exception(e)
  File "c:\users\harry\documents\oddsonglory\odds-on-glory\venv\lib\site-packages\flask\app.py", line 1821, in handle_user_exception
    reraise(exc_type, exc_value, tb)
  File "c:\users\harry\documents\oddsonglory\odds-on-glory\venv\lib\site-packages\flask\_compat.py", line 39, in reraise
    raise value
  File "c:\users\harry\documents\oddsonglory\odds-on-glory\venv\lib\site-packages\flask\app.py", line 1948, in full_dispatch_request
    rv = self.preprocess_request()
  File "c:\users\harry\documents\oddsonglory\odds-on-glory\venv\lib\site-packages\flask\app.py", line 2242, in preprocess_request
    rv = func()
  File "C:\Users\Harry\Documents\OddsOnGlory\odds-on-glory\app\routes.py", line 26, in before_request
    for game_code in active_games:
RuntimeError: dictionary changed size during iteration
2020-06-17 19:23:59,085 INFO: OddsOnGlory Game [in C:\Users\Harry\Documents\OddsOnGlory\odds-on-glory\app\__init__.py:52]
