2020-06-16 15:10:08,539 ERROR: Exception on /add_gladiator_to_arena [POST] [in c:\users\harry\documents\oddsonglory\odds-on-glory\venv\lib\site-packages\flask\app.py:1891]
Traceback (most recent call last):
  File "c:\users\harry\documents\oddsonglory\odds-on-glory\venv\lib\site-packages\flask\app.py", line 2447, in wsgi_app
    response = self.full_dispatch_request()
  File "c:\users\harry\documents\oddsonglory\odds-on-glory\venv\lib\site-packages\flask\app.py", line 1952, in full_dispatch_request
    rv = self.handle_user_exception(e)
  File "c:\users\harry\documents\oddsonglory\odds-on-glory\venv\lib\site-packages\flask\app.py", line 1821, in handle_user_exception
    reraise(exc_type, exc_value, tb)
  File "c:\users\harry\documents\oddsonglory\odds-on-glory\venv\lib\site-packages\flask\_compat.py", line 39, in reraise
    raise value
  File "c:\users\harry\documents\oddsonglory\odds-on-glory\venv\lib\site-packages\flask\app.py", line 1950, in full_dispatch_request
    rv = self.dispatch_request()
  File "c:\users\harry\documents\oddsonglory\odds-on-glory\venv\lib\site-packages\flask\app.py", line 1936, in dispatch_request
    return self.view_functions[rule.endpoint](**req.view_args)
  File "C:\Users\Harry\Documents\OddsOnGlory\odds-on-glory\app\routes.py", line 65, in add_gladiator_to_arena
    json_glad = json.loads(request.form.get('gladiator'))[0]
KeyError: 0
2020-06-16 15:10:21,891 INFO: OddsOnGlory Game [in C:\Users\Harry\Documents\OddsOnGlory\odds-on-glory\app\__init__.py:52]
2020-06-16 15:10:31,285 ERROR: Exception on /add_gladiator_to_arena [POST] [in c:\users\harry\documents\oddsonglory\odds-on-glory\venv\lib\site-packages\flask\app.py:1891]
Traceback (most recent call last):
  File "c:\users\harry\documents\oddsonglory\odds-on-glory\venv\lib\site-packages\flask\app.py", line 2447, in wsgi_app
    response = self.full_dispatch_request()
  File "c:\users\harry\documents\oddsonglory\odds-on-glory\venv\lib\site-packages\flask\app.py", line 1952, in full_dispatch_request
    rv = self.handle_user_exception(e)
  File "c:\users\harry\documents\oddsonglory\odds-on-glory\venv\lib\site-packages\flask\app.py", line 1821, in handle_user_exception
    reraise(exc_type, exc_value, tb)
  File "c:\users\harry\documents\oddsonglory\odds-on-glory\venv\lib\site-packages\flask\_compat.py", line 39, in reraise
    raise value
  File "c:\users\harry\documents\oddsonglory\odds-on-glory\venv\lib\site-packages\flask\app.py", line 1950, in full_dispatch_request
    rv = self.dispatch_request()
  File "c:\users\harry\documents\oddsonglory\odds-on-glory\venv\lib\site-packages\flask\app.py", line 1936, in dispatch_request
    return self.view_functions[rule.endpoint](**req.view_args)
  File "C:\Users\Harry\Documents\OddsOnGlory\odds-on-glory\app\routes.py", line 68, in add_gladiator_to_arena
    print(glad)
NameError: name 'glad' is not defined
2020-06-16 15:10:52,715 INFO: OddsOnGlory Game [in C:\Users\Harry\Documents\OddsOnGlory\odds-on-glory\app\__init__.py:52]
2020-06-16 15:20:05,524 INFO: OddsOnGlory Game [in C:\Users\Harry\Documents\OddsOnGlory\odds-on-glory\app\__init__.py:52]
2020-06-16 15:20:14,327 ERROR: Exception on /add_gladiator_to_arena [POST] [in c:\users\harry\documents\oddsonglory\odds-on-glory\venv\lib\site-packages\flask\app.py:1891]
Traceback (most recent call last):
  File "c:\users\harry\documents\oddsonglory\odds-on-glory\venv\lib\site-packages\flask\app.py", line 2447, in wsgi_app
    response = self.full_dispatch_request()
  File "c:\users\harry\documents\oddsonglory\odds-on-glory\venv\lib\site-packages\flask\app.py", line 1952, in full_dispatch_request
    rv = self.handle_user_exception(e)
  File "c:\users\harry\documents\oddsonglory\odds-on-glory\venv\lib\site-packages\flask\app.py", line 1821, in handle_user_exception
    reraise(exc_type, exc_value, tb)
  File "c:\users\harry\documents\oddsonglory\odds-on-glory\venv\lib\site-packages\flask\_compat.py", line 39, in reraise
    raise value
  File "c:\users\harry\documents\oddsonglory\odds-on-glory\venv\lib\site-packages\flask\app.py", line 1950, in full_dispatch_request
    rv = self.dispatch_request()
  File "c:\users\harry\documents\oddsonglory\odds-on-glory\venv\lib\site-packages\flask\app.py", line 1936, in dispatch_request
    return self.view_functions[rule.endpoint](**req.view_args)
  File "C:\Users\Harry\Documents\OddsOnGlory\odds-on-glory\app\routes.py", line 72, in add_gladiator_to_arena
    game.addGladiator(glad.name, glad.strength, glad.aggro,
  File "C:\Users\Harry\Documents\OddsOnGlory\odds-on-glory\app\game_files\game_handler.py", line 46, in addGladiator
    if (len(self.arena.gladiators) < capacity):
NameError: name 'capacity' is not defined
2020-06-16 15:20:40,841 INFO: OddsOnGlory Game [in C:\Users\Harry\Documents\OddsOnGlory\odds-on-glory\app\__init__.py:52]
2020-06-16 15:24:14,012 INFO: OddsOnGlory Game [in C:\Users\Harry\Documents\OddsOnGlory\odds-on-glory\app\__init__.py:52]
2020-06-16 15:24:29,251 INFO: OddsOnGlory Game [in C:\Users\Harry\Documents\OddsOnGlory\odds-on-glory\app\__init__.py:52]
2020-06-16 15:25:08,182 ERROR: Exception on /send_glad_gift [POST] [in c:\users\harry\documents\oddsonglory\odds-on-glory\venv\lib\site-packages\flask\app.py:1891]
Traceback (most recent call last):
  File "c:\users\harry\documents\oddsonglory\odds-on-glory\venv\lib\site-packages\flask\app.py", line 2447, in wsgi_app
    response = self.full_dispatch_request()
  File "c:\users\harry\documents\oddsonglory\odds-on-glory\venv\lib\site-packages\flask\app.py", line 1952, in full_dispatch_request
    rv = self.handle_user_exception(e)
  File "c:\users\harry\documents\oddsonglory\odds-on-glory\venv\lib\site-packages\flask\app.py", line 1821, in handle_user_exception
    reraise(exc_type, exc_value, tb)
  File "c:\users\harry\documents\oddsonglory\odds-on-glory\venv\lib\site-packages\flask\_compat.py", line 39, in reraise
    raise value
  File "c:\users\harry\documents\oddsonglory\odds-on-glory\venv\lib\site-packages\flask\app.py", line 1950, in full_dispatch_request
    rv = self.dispatch_request()
  File "c:\users\harry\documents\oddsonglory\odds-on-glory\venv\lib\site-packages\flask\app.py", line 1936, in dispatch_request
    return self.view_functions[rule.endpoint](**req.view_args)
  File "C:\Users\Harry\Documents\OddsOnGlory\odds-on-glory\app\routes.py", line 96, in send_glad_gift
    game.sendGift(glad_id, gift) ##gift var currently unused
  File "C:\Users\Harry\Documents\OddsOnGlory\odds-on-glory\app\game_files\game_handler.py", line 62, in sendGift
    runner = Runner(r.choice(nameslist), r.randrange(15), 0, r.randrange(30,99), gladiator, [Gladiator.I_TRAPS, Trap(50, None)])
  File "C:\Users\Harry\Documents\OddsOnGlory\odds-on-glory\app\game_files\gladiator.py", line 401, in __init__
    super().__init__(name, strength, aggro, speed)
TypeError: __init__() missing 1 required positional argument: 'owner'
2020-06-16 15:40:11,724 INFO: OddsOnGlory Game [in C:\Users\Harry\Documents\OddsOnGlory\odds-on-glory\app\__init__.py:52]
2020-06-16 15:41:14,819 INFO: OddsOnGlory Game [in C:\Users\Harry\Documents\OddsOnGlory\odds-on-glory\app\__init__.py:52]
2020-06-16 15:43:28,794 INFO: OddsOnGlory Game [in C:\Users\Harry\Documents\OddsOnGlory\odds-on-glory\app\__init__.py:52]
2020-06-16 15:44:58,027 ERROR: Exception on /send_glad_gift [POST] [in c:\users\harry\documents\oddsonglory\odds-on-glory\venv\lib\site-packages\flask\app.py:1891]
Traceback (most recent call last):
  File "c:\users\harry\documents\oddsonglory\odds-on-glory\venv\lib\site-packages\flask\app.py", line 2447, in wsgi_app
    response = self.full_dispatch_request()
  File "c:\users\harry\documents\oddsonglory\odds-on-glory\venv\lib\site-packages\flask\app.py", line 1952, in full_dispatch_request
    rv = self.handle_user_exception(e)
  File "c:\users\harry\documents\oddsonglory\odds-on-glory\venv\lib\site-packages\flask\app.py", line 1821, in handle_user_exception
    reraise(exc_type, exc_value, tb)
  File "c:\users\harry\documents\oddsonglory\odds-on-glory\venv\lib\site-packages\flask\_compat.py", line 39, in reraise
    raise value
  File "c:\users\harry\documents\oddsonglory\odds-on-glory\venv\lib\site-packages\flask\app.py", line 1950, in full_dispatch_request
    rv = self.dispatch_request()
  File "c:\users\harry\documents\oddsonglory\odds-on-glory\venv\lib\site-packages\flask\app.py", line 1936, in dispatch_request
    return self.view_functions[rule.endpoint](**req.view_args)
  File "C:\Users\Harry\Documents\OddsOnGlory\odds-on-glory\app\routes.py", line 95, in send_glad_gift
    game.sendGift(glad_id, gift) ##gift var currently unused
  File "C:\Users\Harry\Documents\OddsOnGlory\odds-on-glory\app\game_files\game_handler.py", line 62, in sendGift
    runner = Runner(r.choice(nameslist), r.randrange(15), 0, r.randrange(30,99), gladiator, [Gladiator.I_TRAPS, Trap(50, None)])
  File "C:\Users\Harry\Documents\OddsOnGlory\odds-on-glory\app\game_files\gladiator.py", line 405, in __init__
    super().__init__(name, strength, aggro, speed)
TypeError: __init__() missing 1 required positional argument: 'ext_id'
