2020-06-29 14:30:59,561 ERROR: Exception on /user/harry [GET] [in c:\users\harry\documents\oddsonglory\odds-on-glory\venv\lib\site-packages\flask\app.py:1891]
Traceback (most recent call last):
  File "c:\users\harry\documents\oddsonglory\odds-on-glory\venv\lib\site-packages\flask\app.py", line 2447, in wsgi_app
    response = self.full_dispatch_request()
  File "c:\users\harry\documents\oddsonglory\odds-on-glory\venv\lib\site-packages\flask\app.py", line 1952, in full_dispatch_request
    rv = self.handle_user_exception(e)
  File "c:\users\harry\documents\oddsonglory\odds-on-glory\venv\lib\site-packages\flask\app.py", line 1821, in handle_user_exception
    reraise(exc_type, exc_value, tb)
  File "c:\users\harry\documents\oddsonglory\odds-on-glory\venv\lib\site-packages\flask\_compat.py", line 39, in reraise
    raise value
  File "c:\users\harry\documents\oddsonglory\odds-on-glory\venv\lib\site-packages\flask\app.py", line 1950, in full_dispatch_request
    rv = self.dispatch_request()
  File "c:\users\harry\documents\oddsonglory\odds-on-glory\venv\lib\site-packages\flask\app.py", line 1936, in dispatch_request
    return self.view_functions[rule.endpoint](**req.view_args)
  File "c:\users\harry\documents\oddsonglory\odds-on-glory\venv\lib\site-packages\flask_login\utils.py", line 272, in decorated_view
    return func(*args, **kwargs)
  File "C:\Users\Harry\Documents\OddsOnGlory\odds-on-glory\app\routes.py", line 253, in user
    print(moment(current_user.last_bonus).fromNow())
TypeError: 'Moment' object is not callable
2020-06-29 14:31:02,080 ERROR: Exception on /user/harry [GET] [in c:\users\harry\documents\oddsonglory\odds-on-glory\venv\lib\site-packages\flask\app.py:1891]
Traceback (most recent call last):
  File "c:\users\harry\documents\oddsonglory\odds-on-glory\venv\lib\site-packages\flask\app.py", line 2447, in wsgi_app
    response = self.full_dispatch_request()
  File "c:\users\harry\documents\oddsonglory\odds-on-glory\venv\lib\site-packages\flask\app.py", line 1952, in full_dispatch_request
    rv = self.handle_user_exception(e)
  File "c:\users\harry\documents\oddsonglory\odds-on-glory\venv\lib\site-packages\flask\app.py", line 1821, in handle_user_exception
    reraise(exc_type, exc_value, tb)
  File "c:\users\harry\documents\oddsonglory\odds-on-glory\venv\lib\site-packages\flask\_compat.py", line 39, in reraise
    raise value
  File "c:\users\harry\documents\oddsonglory\odds-on-glory\venv\lib\site-packages\flask\app.py", line 1950, in full_dispatch_request
    rv = self.dispatch_request()
  File "c:\users\harry\documents\oddsonglory\odds-on-glory\venv\lib\site-packages\flask\app.py", line 1936, in dispatch_request
    return self.view_functions[rule.endpoint](**req.view_args)
  File "c:\users\harry\documents\oddsonglory\odds-on-glory\venv\lib\site-packages\flask_login\utils.py", line 272, in decorated_view
    return func(*args, **kwargs)
  File "C:\Users\Harry\Documents\OddsOnGlory\odds-on-glory\app\routes.py", line 253, in user
    print(moment(current_user.last_bonus).fromNow())
TypeError: 'Moment' object is not callable
2020-06-29 14:34:39,218 INFO: OddsOnGlory Game [in C:\Users\Harry\Documents\OddsOnGlory\odds-on-glory\app\__init__.py:55]
2020-06-29 14:35:53,655 INFO: OddsOnGlory Game [in C:\Users\Harry\Documents\OddsOnGlory\odds-on-glory\app\__init__.py:55]
2020-06-29 14:36:31,490 INFO: OddsOnGlory Game [in C:\Users\Harry\Documents\OddsOnGlory\odds-on-glory\app\__init__.py:55]
2020-06-29 14:53:18,848 INFO: OddsOnGlory Game [in C:\Users\Harry\Documents\OddsOnGlory\odds-on-glory\app\__init__.py:55]
2020-06-29 14:53:30,574 ERROR: Exception on / [GET] [in c:\users\harry\documents\oddsonglory\odds-on-glory\venv\lib\site-packages\flask\app.py:1891]
Traceback (most recent call last):
  File "c:\users\harry\documents\oddsonglory\odds-on-glory\venv\lib\site-packages\sqlalchemy\engine\base.py", line 1211, in _execute_context
    context = constructor(dialect, self, conn, *args)
  File "c:\users\harry\documents\oddsonglory\odds-on-glory\venv\lib\site-packages\sqlalchemy\engine\default.py", line 836, in _init_compiled
    param.append(processors[key](compiled_params[key]))
  File "c:\users\harry\documents\oddsonglory\odds-on-glory\venv\lib\site-packages\sqlalchemy\dialects\sqlite\base.py", line 771, in process
    raise TypeError(
TypeError: SQLite DateTime type only accepts Python datetime and date objects as input.

The above exception was the direct cause of the following exception:

Traceback (most recent call last):
  File "c:\users\harry\documents\oddsonglory\odds-on-glory\venv\lib\site-packages\flask\app.py", line 2447, in wsgi_app
    response = self.full_dispatch_request()
  File "c:\users\harry\documents\oddsonglory\odds-on-glory\venv\lib\site-packages\flask\app.py", line 1952, in full_dispatch_request
    rv = self.handle_user_exception(e)
  File "c:\users\harry\documents\oddsonglory\odds-on-glory\venv\lib\site-packages\flask\app.py", line 1821, in handle_user_exception
    reraise(exc_type, exc_value, tb)
  File "c:\users\harry\documents\oddsonglory\odds-on-glory\venv\lib\site-packages\flask\_compat.py", line 39, in reraise
    raise value
  File "c:\users\harry\documents\oddsonglory\odds-on-glory\venv\lib\site-packages\flask\app.py", line 1950, in full_dispatch_request
    rv = self.dispatch_request()
  File "c:\users\harry\documents\oddsonglory\odds-on-glory\venv\lib\site-packages\flask\app.py", line 1936, in dispatch_request
    return self.view_functions[rule.endpoint](**req.view_args)
  File "c:\users\harry\documents\oddsonglory\odds-on-glory\venv\lib\site-packages\flask_login\utils.py", line 272, in decorated_view
    return func(*args, **kwargs)
  File "C:\Users\Harry\Documents\OddsOnGlory\odds-on-glory\app\routes.py", line 168, in index
    db.session.commit()
  File "c:\users\harry\documents\oddsonglory\odds-on-glory\venv\lib\site-packages\sqlalchemy\orm\scoping.py", line 163, in do
    return getattr(self.registry(), name)(*args, **kwargs)
  File "c:\users\harry\documents\oddsonglory\odds-on-glory\venv\lib\site-packages\sqlalchemy\orm\session.py", line 1042, in commit
    self.transaction.commit()
  File "c:\users\harry\documents\oddsonglory\odds-on-glory\venv\lib\site-packages\sqlalchemy\orm\session.py", line 504, in commit
    self._prepare_impl()
  File "c:\users\harry\documents\oddsonglory\odds-on-glory\venv\lib\site-packages\sqlalchemy\orm\session.py", line 483, in _prepare_impl
    self.session.flush()
  File "c:\users\harry\documents\oddsonglory\odds-on-glory\venv\lib\site-packages\sqlalchemy\orm\session.py", line 2523, in flush
    self._flush(objects)
  File "c:\users\harry\documents\oddsonglory\odds-on-glory\venv\lib\site-packages\sqlalchemy\orm\session.py", line 2664, in _flush
    transaction.rollback(_capture_exception=True)
  File "c:\users\harry\documents\oddsonglory\odds-on-glory\venv\lib\site-packages\sqlalchemy\util\langhelpers.py", line 68, in __exit__
    compat.raise_(
  File "c:\users\harry\documents\oddsonglory\odds-on-glory\venv\lib\site-packages\sqlalchemy\util\compat.py", line 178, in raise_
    raise exception
  File "c:\users\harry\documents\oddsonglory\odds-on-glory\venv\lib\site-packages\sqlalchemy\orm\session.py", line 2624, in _flush
    flush_context.execute()
  File "c:\users\harry\documents\oddsonglory\odds-on-glory\venv\lib\site-packages\sqlalchemy\orm\unitofwork.py", line 422, in execute
    rec.execute(self)
  File "c:\users\harry\documents\oddsonglory\odds-on-glory\venv\lib\site-packages\sqlalchemy\orm\unitofwork.py", line 586, in execute
    persistence.save_obj(
  File "c:\users\harry\documents\oddsonglory\odds-on-glory\venv\lib\site-packages\sqlalchemy\orm\persistence.py", line 230, in save_obj
    _emit_update_statements(
  File "c:\users\harry\documents\oddsonglory\odds-on-glory\venv\lib\site-packages\sqlalchemy\orm\persistence.py", line 994, in _emit_update_statements
    c = cached_connections[connection].execute(
  File "c:\users\harry\documents\oddsonglory\odds-on-glory\venv\lib\site-packages\sqlalchemy\engine\base.py", line 1020, in execute
    return meth(self, multiparams, params)
  File "c:\users\harry\documents\oddsonglory\odds-on-glory\venv\lib\site-packages\sqlalchemy\sql\elements.py", line 298, in _execute_on_connection
    return connection._execute_clauseelement(self, multiparams, params)
  File "c:\users\harry\documents\oddsonglory\odds-on-glory\venv\lib\site-packages\sqlalchemy\engine\base.py", line 1133, in _execute_clauseelement
    ret = self._execute_context(
  File "c:\users\harry\documents\oddsonglory\odds-on-glory\venv\lib\site-packages\sqlalchemy\engine\base.py", line 1213, in _execute_context
    self._handle_dbapi_exception(
  File "c:\users\harry\documents\oddsonglory\odds-on-glory\venv\lib\site-packages\sqlalchemy\engine\base.py", line 1517, in _handle_dbapi_exception
    util.raise_(
  File "c:\users\harry\documents\oddsonglory\odds-on-glory\venv\lib\site-packages\sqlalchemy\util\compat.py", line 178, in raise_
    raise exception
  File "c:\users\harry\documents\oddsonglory\odds-on-glory\venv\lib\site-packages\sqlalchemy\engine\base.py", line 1211, in _execute_context
    context = constructor(dialect, self, conn, *args)
  File "c:\users\harry\documents\oddsonglory\odds-on-glory\venv\lib\site-packages\sqlalchemy\engine\default.py", line 836, in _init_compiled
    param.append(processors[key](compiled_params[key]))
  File "c:\users\harry\documents\oddsonglory\odds-on-glory\venv\lib\site-packages\sqlalchemy\dialects\sqlite\base.py", line 771, in process
    raise TypeError(
sqlalchemy.exc.StatementError: (builtins.TypeError) SQLite DateTime type only accepts Python datetime and date objects as input.
[SQL: UPDATE user SET last_bonus=? WHERE user.id = ?]
[parameters: [{'last_bonus': <built-in method utcnow of type object at 0x00007FFF6AC8B530>, 'user_id': 1}, {'last_bonus': <built-in method utcnow of type object at ... (444 characters truncated) ... now of type object at 0x00007FFF6AC8B530>, 'user_id': 7}, {'last_bonus': <built-in method utcnow of type object at 0x00007FFF6AC8B530>, 'user_id': 8}]]
