2020-06-09 20:01:58,821 ERROR: Exception on /host_game [GET] [in C:\Users\Harry\Documents\OddsOnGlory\odds-on-glory\venv\lib\site-packages\flask\app.py:1891]
Traceback (most recent call last):
  File "C:\Users\Harry\Documents\OddsOnGlory\odds-on-glory\venv\lib\site-packages\flask\app.py", line 2447, in wsgi_app
    response = self.full_dispatch_request()
  File "C:\Users\Harry\Documents\OddsOnGlory\odds-on-glory\venv\lib\site-packages\flask\app.py", line 1952, in full_dispatch_request
    rv = self.handle_user_exception(e)
  File "C:\Users\Harry\Documents\OddsOnGlory\odds-on-glory\venv\lib\site-packages\flask\app.py", line 1821, in handle_user_exception
    reraise(exc_type, exc_value, tb)
  File "C:\Users\Harry\Documents\OddsOnGlory\odds-on-glory\venv\lib\site-packages\flask\_compat.py", line 39, in reraise
    raise value
  File "C:\Users\Harry\Documents\OddsOnGlory\odds-on-glory\venv\lib\site-packages\flask\app.py", line 1950, in full_dispatch_request
    rv = self.dispatch_request()
  File "C:\Users\Harry\Documents\OddsOnGlory\odds-on-glory\venv\lib\site-packages\flask\app.py", line 1936, in dispatch_request
    return self.view_functions[rule.endpoint](**req.view_args)
  File "C:\Users\Harry\Documents\OddsOnGlory\odds-on-glory\venv\lib\site-packages\flask_login\utils.py", line 272, in decorated_view
    return func(*args, **kwargs)
  File "C:\Users\Harry\Documents\OddsOnGlory\odds-on-glory\app\routes.py", line 38, in host_game
    game_handler = GameHandler(socketio, game.code, game_id)
NameError: name 'game_id' is not defined
2020-06-09 20:02:29,636 INFO: OddsOnGlory Game [in C:\Users\Harry\Documents\OddsOnGlory\odds-on-glory\app\__init__.py:49]
2020-06-09 20:02:33,603 ERROR: Exception on /host_game [GET] [in C:\Users\Harry\Documents\OddsOnGlory\odds-on-glory\venv\lib\site-packages\flask\app.py:1891]
Traceback (most recent call last):
  File "C:\Users\Harry\Documents\OddsOnGlory\odds-on-glory\venv\lib\site-packages\flask\app.py", line 2447, in wsgi_app
    response = self.full_dispatch_request()
  File "C:\Users\Harry\Documents\OddsOnGlory\odds-on-glory\venv\lib\site-packages\flask\app.py", line 1952, in full_dispatch_request
    rv = self.handle_user_exception(e)
  File "C:\Users\Harry\Documents\OddsOnGlory\odds-on-glory\venv\lib\site-packages\flask\app.py", line 1821, in handle_user_exception
    reraise(exc_type, exc_value, tb)
  File "C:\Users\Harry\Documents\OddsOnGlory\odds-on-glory\venv\lib\site-packages\flask\_compat.py", line 39, in reraise
    raise value
  File "C:\Users\Harry\Documents\OddsOnGlory\odds-on-glory\venv\lib\site-packages\flask\app.py", line 1950, in full_dispatch_request
    rv = self.dispatch_request()
  File "C:\Users\Harry\Documents\OddsOnGlory\odds-on-glory\venv\lib\site-packages\flask\app.py", line 1936, in dispatch_request
    return self.view_functions[rule.endpoint](**req.view_args)
  File "C:\Users\Harry\Documents\OddsOnGlory\odds-on-glory\venv\lib\site-packages\flask_login\utils.py", line 272, in decorated_view
    return func(*args, **kwargs)
  File "C:\Users\Harry\Documents\OddsOnGlory\odds-on-glory\app\routes.py", line 38, in host_game
    game_handler = GameHandler(socketio, game.code, game.id)
  File "C:\Users\Harry\Documents\OddsOnGlory\odds-on-glory\app\game_files\game_handler.py", line 24, in __init__
    for _ in range(no_glad):
NameError: name 'no_glad' is not defined
2020-06-09 20:02:55,025 INFO: OddsOnGlory Game [in C:\Users\Harry\Documents\OddsOnGlory\odds-on-glory\app\__init__.py:49]
2020-06-09 20:02:58,493 ERROR: Exception on /host_game [GET] [in C:\Users\Harry\Documents\OddsOnGlory\odds-on-glory\venv\lib\site-packages\flask\app.py:1891]
Traceback (most recent call last):
  File "C:\Users\Harry\Documents\OddsOnGlory\odds-on-glory\venv\lib\site-packages\flask\app.py", line 2447, in wsgi_app
    response = self.full_dispatch_request()
  File "C:\Users\Harry\Documents\OddsOnGlory\odds-on-glory\venv\lib\site-packages\flask\app.py", line 1952, in full_dispatch_request
    rv = self.handle_user_exception(e)
  File "C:\Users\Harry\Documents\OddsOnGlory\odds-on-glory\venv\lib\site-packages\flask\app.py", line 1821, in handle_user_exception
    reraise(exc_type, exc_value, tb)
  File "C:\Users\Harry\Documents\OddsOnGlory\odds-on-glory\venv\lib\site-packages\flask\_compat.py", line 39, in reraise
    raise value
  File "C:\Users\Harry\Documents\OddsOnGlory\odds-on-glory\venv\lib\site-packages\flask\app.py", line 1950, in full_dispatch_request
    rv = self.dispatch_request()
  File "C:\Users\Harry\Documents\OddsOnGlory\odds-on-glory\venv\lib\site-packages\flask\app.py", line 1936, in dispatch_request
    return self.view_functions[rule.endpoint](**req.view_args)
  File "C:\Users\Harry\Documents\OddsOnGlory\odds-on-glory\venv\lib\site-packages\flask_login\utils.py", line 272, in decorated_view
    return func(*args, **kwargs)
  File "C:\Users\Harry\Documents\OddsOnGlory\odds-on-glory\app\routes.py", line 39, in host_game
    active_games[game.id] = game_handler
IndexError: list assignment index out of range
2020-06-09 20:03:23,507 INFO: OddsOnGlory Game [in C:\Users\Harry\Documents\OddsOnGlory\odds-on-glory\app\__init__.py:49]
2020-06-09 20:03:26,395 ERROR: Exception on /host_game [GET] [in C:\Users\Harry\Documents\OddsOnGlory\odds-on-glory\venv\lib\site-packages\flask\app.py:1891]
Traceback (most recent call last):
  File "C:\Users\Harry\Documents\OddsOnGlory\odds-on-glory\venv\lib\site-packages\flask\app.py", line 2447, in wsgi_app
    response = self.full_dispatch_request()
  File "C:\Users\Harry\Documents\OddsOnGlory\odds-on-glory\venv\lib\site-packages\flask\app.py", line 1952, in full_dispatch_request
    rv = self.handle_user_exception(e)
  File "C:\Users\Harry\Documents\OddsOnGlory\odds-on-glory\venv\lib\site-packages\flask\app.py", line 1821, in handle_user_exception
    reraise(exc_type, exc_value, tb)
  File "C:\Users\Harry\Documents\OddsOnGlory\odds-on-glory\venv\lib\site-packages\flask\_compat.py", line 39, in reraise
    raise value
  File "C:\Users\Harry\Documents\OddsOnGlory\odds-on-glory\venv\lib\site-packages\flask\app.py", line 1950, in full_dispatch_request
    rv = self.dispatch_request()
  File "C:\Users\Harry\Documents\OddsOnGlory\odds-on-glory\venv\lib\site-packages\flask\app.py", line 1936, in dispatch_request
    return self.view_functions[rule.endpoint](**req.view_args)
  File "C:\Users\Harry\Documents\OddsOnGlory\odds-on-glory\venv\lib\site-packages\flask_login\utils.py", line 272, in decorated_view
    return func(*args, **kwargs)
  File "C:\Users\Harry\Documents\OddsOnGlory\odds-on-glory\app\routes.py", line 42, in host_game
    thread = socketio.start_background_task(game_handler.tempGoForThis())
  File "C:\Users\Harry\Documents\OddsOnGlory\odds-on-glory\app\game_files\game_handler.py", line 35, in tempGoForThis
    self.preGameDisplay()
  File "C:\Users\Harry\Documents\OddsOnGlory\odds-on-glory\app\game_files\game_handler.py", line 39, in preGameDisplay
    json_obj = pushInfoToJSON(self.arena)
  File "C:\Users\Harry\Documents\OddsOnGlory\odds-on-glory\app\game_files\convertToJSON.py", line 19, in pushInfoToJSON
    tile_row["row_no"] = tile_row[0].y_pos
KeyError: 0
2020-06-09 21:03:04,217 INFO: OddsOnGlory Game [in C:\Users\Harry\Documents\OddsOnGlory\odds-on-glory\app\__init__.py:49]
2020-06-09 21:03:10,493 ERROR: Exception on /host_game [GET] [in C:\Users\Harry\Documents\OddsOnGlory\odds-on-glory\venv\lib\site-packages\flask\app.py:1891]
Traceback (most recent call last):
  File "C:\Users\Harry\Documents\OddsOnGlory\odds-on-glory\venv\lib\site-packages\flask\app.py", line 2447, in wsgi_app
    response = self.full_dispatch_request()
  File "C:\Users\Harry\Documents\OddsOnGlory\odds-on-glory\venv\lib\site-packages\flask\app.py", line 1952, in full_dispatch_request
    rv = self.handle_user_exception(e)
  File "C:\Users\Harry\Documents\OddsOnGlory\odds-on-glory\venv\lib\site-packages\flask\app.py", line 1821, in handle_user_exception
    reraise(exc_type, exc_value, tb)
  File "C:\Users\Harry\Documents\OddsOnGlory\odds-on-glory\venv\lib\site-packages\flask\_compat.py", line 39, in reraise
    raise value
  File "C:\Users\Harry\Documents\OddsOnGlory\odds-on-glory\venv\lib\site-packages\flask\app.py", line 1950, in full_dispatch_request
    rv = self.dispatch_request()
  File "C:\Users\Harry\Documents\OddsOnGlory\odds-on-glory\venv\lib\site-packages\flask\app.py", line 1936, in dispatch_request
    return self.view_functions[rule.endpoint](**req.view_args)
  File "C:\Users\Harry\Documents\OddsOnGlory\odds-on-glory\venv\lib\site-packages\flask_login\utils.py", line 272, in decorated_view
    return func(*args, **kwargs)
  File "C:\Users\Harry\Documents\OddsOnGlory\odds-on-glory\app\routes.py", line 42, in host_game
    thread = socketio.start_background_task(game_handler.tempGoForThis())
  File "C:\Users\Harry\Documents\OddsOnGlory\odds-on-glory\app\game_files\game_handler.py", line 35, in tempGoForThis
    self.preGameDisplay()
  File "C:\Users\Harry\Documents\OddsOnGlory\odds-on-glory\app\game_files\game_handler.py", line 39, in preGameDisplay
    json_obj = pushInfoToJSON(self.arena)
  File "C:\Users\Harry\Documents\OddsOnGlory\odds-on-glory\app\game_files\convertToJSON.py", line 72, in pushInfoToJSON
    json_arena = json.dumps(arena_info)
  File "C:\Users\Harry\AppData\Local\Programs\Python\Python38\lib\json\__init__.py", line 231, in dumps
    return _default_encoder.encode(obj)
  File "C:\Users\Harry\AppData\Local\Programs\Python\Python38\lib\json\encoder.py", line 199, in encode
    chunks = self.iterencode(o, _one_shot=True)
  File "C:\Users\Harry\AppData\Local\Programs\Python\Python38\lib\json\encoder.py", line 257, in iterencode
    return _iterencode(o, 0)
  File "C:\Users\Harry\AppData\Local\Programs\Python\Python38\lib\json\encoder.py", line 179, in default
    raise TypeError(f'Object of type {o.__class__.__name__} '
TypeError: Object of type Tile is not JSON serializable
2020-06-09 21:04:11,696 INFO: OddsOnGlory Game [in C:\Users\Harry\Documents\OddsOnGlory\odds-on-glory\app\__init__.py:49]
