2020-06-13 19:35:05,081 INFO: OddsOnGlory Game [in C:\Users\Harry\Documents\OddsOnGlory\odds-on-glory\app\__init__.py:49]
2020-06-13 19:41:36,836 INFO: OddsOnGlory Game [in C:\Users\Harry\Documents\OddsOnGlory\odds-on-glory\app\__init__.py:49]
2020-06-13 20:42:29,712 INFO: OddsOnGlory Game [in C:\Users\Harry\Documents\OddsOnGlory\odds-on-glory\app\__init__.py:49]
2020-06-14 11:07:07,985 INFO: OddsOnGlory Game [in C:\Users\Harry\Documents\OddsOnGlory\odds-on-glory\app\__init__.py:49]
2020-06-14 11:14:54,036 INFO: OddsOnGlory Game [in C:\Users\Harry\Documents\OddsOnGlory\odds-on-glory\app\__init__.py:49]
2020-06-14 11:16:14,121 INFO: OddsOnGlory Game [in C:\Users\Harry\Documents\OddsOnGlory\odds-on-glory\app\__init__.py:49]
2020-06-14 11:16:49,216 INFO: OddsOnGlory Game [in C:\Users\Harry\Documents\OddsOnGlory\odds-on-glory\app\__init__.py:49]
2020-06-14 11:20:20,204 INFO: OddsOnGlory Game [in C:\Users\Harry\Documents\OddsOnGlory\odds-on-glory\app\__init__.py:49]
2020-06-14 11:25:30,897 INFO: OddsOnGlory Game [in C:\Users\Harry\Documents\OddsOnGlory\odds-on-glory\app\__init__.py:49]
2020-06-14 11:28:44,263 INFO: OddsOnGlory Game [in C:\Users\Harry\Documents\OddsOnGlory\odds-on-glory\app\__init__.py:49]
2020-06-14 11:29:55,710 INFO: OddsOnGlory Game [in C:\Users\Harry\Documents\OddsOnGlory\odds-on-glory\app\__init__.py:49]
2020-06-14 11:31:26,722 INFO: OddsOnGlory Game [in C:\Users\Harry\Documents\OddsOnGlory\odds-on-glory\app\__init__.py:49]
2020-06-14 11:32:36,911 INFO: OddsOnGlory Game [in C:\Users\Harry\Documents\OddsOnGlory\odds-on-glory\app\__init__.py:49]
2020-06-14 11:39:20,845 INFO: OddsOnGlory Game [in C:\Users\Harry\Documents\OddsOnGlory\odds-on-glory\app\__init__.py:49]
2020-06-14 11:41:37,268 INFO: OddsOnGlory Game [in C:\Users\Harry\Documents\OddsOnGlory\odds-on-glory\app\__init__.py:49]
2020-06-14 11:46:34,390 INFO: OddsOnGlory Game [in C:\Users\Harry\Documents\OddsOnGlory\odds-on-glory\app\__init__.py:49]
2020-06-14 11:50:17,893 INFO: OddsOnGlory Game [in C:\Users\Harry\Documents\OddsOnGlory\odds-on-glory\app\__init__.py:49]
2020-06-14 11:50:40,307 INFO: OddsOnGlory Game [in C:\Users\Harry\Documents\OddsOnGlory\odds-on-glory\app\__init__.py:49]
2020-06-14 11:51:34,599 INFO: OddsOnGlory Game [in C:\Users\Harry\Documents\OddsOnGlory\odds-on-glory\app\__init__.py:49]
2020-06-14 11:53:17,441 INFO: OddsOnGlory Game [in C:\Users\Harry\Documents\OddsOnGlory\odds-on-glory\app\__init__.py:49]
2020-06-14 11:55:41,265 INFO: OddsOnGlory Game [in C:\Users\Harry\Documents\OddsOnGlory\odds-on-glory\app\__init__.py:49]
2020-06-14 12:11:18,522 INFO: OddsOnGlory Game [in C:\Users\Harry\Documents\OddsOnGlory\odds-on-glory\app\__init__.py:49]
2020-06-14 12:12:45,812 INFO: OddsOnGlory Game [in C:\Users\Harry\Documents\OddsOnGlory\odds-on-glory\app\__init__.py:49]
2020-06-14 12:13:30,782 INFO: OddsOnGlory Game [in C:\Users\Harry\Documents\OddsOnGlory\odds-on-glory\app\__init__.py:49]
2020-06-14 12:14:08,573 INFO: OddsOnGlory Game [in C:\Users\Harry\Documents\OddsOnGlory\odds-on-glory\app\__init__.py:49]
2020-06-14 12:16:27,154 INFO: OddsOnGlory Game [in C:\Users\Harry\Documents\OddsOnGlory\odds-on-glory\app\__init__.py:49]
2020-06-14 12:19:45,073 INFO: OddsOnGlory Game [in C:\Users\Harry\Documents\OddsOnGlory\odds-on-glory\app\__init__.py:49]
2020-06-14 12:24:46,010 INFO: OddsOnGlory Game [in C:\Users\Harry\Documents\OddsOnGlory\odds-on-glory\app\__init__.py:49]
2020-06-14 12:25:34,953 INFO: OddsOnGlory Game [in C:\Users\Harry\Documents\OddsOnGlory\odds-on-glory\app\__init__.py:49]
2020-06-14 12:26:47,491 INFO: OddsOnGlory Game [in C:\Users\Harry\Documents\OddsOnGlory\odds-on-glory\app\__init__.py:49]
2020-06-14 14:59:46,642 INFO: OddsOnGlory Game [in C:\Users\Harry\Documents\OddsOnGlory\odds-on-glory\app\__init__.py:49]
2020-06-14 14:59:58,256 INFO: OddsOnGlory Game [in C:\Users\Harry\Documents\OddsOnGlory\odds-on-glory\app\__init__.py:49]
2020-06-14 15:00:11,324 ERROR: Exception on /user/Harry [GET] [in C:\Users\Harry\Documents\OddsOnGlory\odds-on-glory\venv\lib\site-packages\flask\app.py:1891]
Traceback (most recent call last):
  File "C:\Users\Harry\Documents\OddsOnGlory\odds-on-glory\venv\lib\site-packages\sqlalchemy\engine\base.py", line 1283, in _execute_context
    self.dialect.do_execute(
  File "C:\Users\Harry\Documents\OddsOnGlory\odds-on-glory\venv\lib\site-packages\sqlalchemy\engine\default.py", line 590, in do_execute
    cursor.execute(statement, parameters)
sqlite3.OperationalError: no such column: user.money

The above exception was the direct cause of the following exception:

Traceback (most recent call last):
  File "C:\Users\Harry\Documents\OddsOnGlory\odds-on-glory\venv\lib\site-packages\flask\app.py", line 2447, in wsgi_app
    response = self.full_dispatch_request()
  File "C:\Users\Harry\Documents\OddsOnGlory\odds-on-glory\venv\lib\site-packages\flask\app.py", line 1952, in full_dispatch_request
    rv = self.handle_user_exception(e)
  File "C:\Users\Harry\Documents\OddsOnGlory\odds-on-glory\venv\lib\site-packages\flask\app.py", line 1821, in handle_user_exception
    reraise(exc_type, exc_value, tb)
  File "C:\Users\Harry\Documents\OddsOnGlory\odds-on-glory\venv\lib\site-packages\flask\_compat.py", line 39, in reraise
    raise value
  File "C:\Users\Harry\Documents\OddsOnGlory\odds-on-glory\venv\lib\site-packages\flask\app.py", line 1948, in full_dispatch_request
    rv = self.preprocess_request()
  File "C:\Users\Harry\Documents\OddsOnGlory\odds-on-glory\venv\lib\site-packages\flask\app.py", line 2242, in preprocess_request
    rv = func()
  File "C:\Users\Harry\Documents\OddsOnGlory\odds-on-glory\app\routes.py", line 21, in before_request
    if current_user.is_authenticated:
  File "C:\Users\Harry\Documents\OddsOnGlory\odds-on-glory\venv\lib\site-packages\werkzeug\local.py", line 347, in __getattr__
    return getattr(self._get_current_object(), name)
  File "C:\Users\Harry\Documents\OddsOnGlory\odds-on-glory\venv\lib\site-packages\werkzeug\local.py", line 306, in _get_current_object
    return self.__local()
  File "C:\Users\Harry\Documents\OddsOnGlory\odds-on-glory\venv\lib\site-packages\flask_login\utils.py", line 26, in <lambda>
    current_user = LocalProxy(lambda: _get_user())
  File "C:\Users\Harry\Documents\OddsOnGlory\odds-on-glory\venv\lib\site-packages\flask_login\utils.py", line 346, in _get_user
    current_app.login_manager._load_user()
  File "C:\Users\Harry\Documents\OddsOnGlory\odds-on-glory\venv\lib\site-packages\flask_login\login_manager.py", line 318, in _load_user
    user = self._user_callback(user_id)
  File "C:\Users\Harry\Documents\OddsOnGlory\odds-on-glory\app\models.py", line 11, in load_user
    return User.query.get(int(id))
  File "C:\Users\Harry\Documents\OddsOnGlory\odds-on-glory\venv\lib\site-packages\sqlalchemy\orm\query.py", line 1021, in get
    return self._get_impl(ident, loading.load_on_pk_identity)
  File "C:\Users\Harry\Documents\OddsOnGlory\odds-on-glory\venv\lib\site-packages\sqlalchemy\orm\query.py", line 1138, in _get_impl
    return db_load_fn(self, primary_key_identity)
  File "C:\Users\Harry\Documents\OddsOnGlory\odds-on-glory\venv\lib\site-packages\sqlalchemy\orm\loading.py", line 287, in load_on_pk_identity
    return q.one()
  File "C:\Users\Harry\Documents\OddsOnGlory\odds-on-glory\venv\lib\site-packages\sqlalchemy\orm\query.py", line 3436, in one
    ret = self.one_or_none()
  File "C:\Users\Harry\Documents\OddsOnGlory\odds-on-glory\venv\lib\site-packages\sqlalchemy\orm\query.py", line 3405, in one_or_none
    ret = list(self)
  File "C:\Users\Harry\Documents\OddsOnGlory\odds-on-glory\venv\lib\site-packages\sqlalchemy\orm\query.py", line 3481, in __iter__
    return self._execute_and_instances(context)
  File "C:\Users\Harry\Documents\OddsOnGlory\odds-on-glory\venv\lib\site-packages\sqlalchemy\orm\query.py", line 3506, in _execute_and_instances
    result = conn.execute(querycontext.statement, self._params)
  File "C:\Users\Harry\Documents\OddsOnGlory\odds-on-glory\venv\lib\site-packages\sqlalchemy\engine\base.py", line 1020, in execute
    return meth(self, multiparams, params)
  File "C:\Users\Harry\Documents\OddsOnGlory\odds-on-glory\venv\lib\site-packages\sqlalchemy\sql\elements.py", line 298, in _execute_on_connection
    return connection._execute_clauseelement(self, multiparams, params)
  File "C:\Users\Harry\Documents\OddsOnGlory\odds-on-glory\venv\lib\site-packages\sqlalchemy\engine\base.py", line 1133, in _execute_clauseelement
    ret = self._execute_context(
  File "C:\Users\Harry\Documents\OddsOnGlory\odds-on-glory\venv\lib\site-packages\sqlalchemy\engine\base.py", line 1323, in _execute_context
    self._handle_dbapi_exception(
  File "C:\Users\Harry\Documents\OddsOnGlory\odds-on-glory\venv\lib\site-packages\sqlalchemy\engine\base.py", line 1517, in _handle_dbapi_exception
    util.raise_(
  File "C:\Users\Harry\Documents\OddsOnGlory\odds-on-glory\venv\lib\site-packages\sqlalchemy\util\compat.py", line 178, in raise_
    raise exception
  File "C:\Users\Harry\Documents\OddsOnGlory\odds-on-glory\venv\lib\site-packages\sqlalchemy\engine\base.py", line 1283, in _execute_context
    self.dialect.do_execute(
  File "C:\Users\Harry\Documents\OddsOnGlory\odds-on-glory\venv\lib\site-packages\sqlalchemy\engine\default.py", line 590, in do_execute
    cursor.execute(statement, parameters)
sqlalchemy.exc.OperationalError: (sqlite3.OperationalError) no such column: user.money
[SQL: SELECT user.id AS user_id, user.username AS user_username, user.email AS user_email, user.password_hash AS user_password_hash, user.about_me AS user_about_me, user.last_seen AS user_last_seen, user.money AS user_money 
FROM user 
WHERE user.id = ?]
[parameters: (1,)]
(Background on this error at: http://sqlalche.me/e/e3q8)
2020-06-14 15:00:23,314 INFO: OddsOnGlory Game [in C:\Users\Harry\Documents\OddsOnGlory\odds-on-glory\app\__init__.py:49]
2020-06-14 15:00:27,700 INFO: OddsOnGlory Game [in C:\Users\Harry\Documents\OddsOnGlory\odds-on-glory\app\__init__.py:49]
2020-06-14 15:00:33,953 INFO: OddsOnGlory Game [in C:\Users\Harry\Documents\OddsOnGlory\odds-on-glory\app\__init__.py:49]
