2020-07-04 10:17:16,073 ERROR: Exception on /user/harry [GET] [in c:\users\harry\documents\oddsonglory\odds-on-glory\venv\lib\site-packages\flask\app.py:1891]
Traceback (most recent call last):
  File "c:\users\harry\documents\oddsonglory\odds-on-glory\venv\lib\site-packages\flask\app.py", line 2447, in wsgi_app
    response = self.full_dispatch_request()
  File "c:\users\harry\documents\oddsonglory\odds-on-glory\venv\lib\site-packages\flask\app.py", line 1952, in full_dispatch_request
    rv = self.handle_user_exception(e)
  File "c:\users\harry\documents\oddsonglory\odds-on-glory\venv\lib\site-packages\flask\app.py", line 1821, in handle_user_exception
    reraise(exc_type, exc_value, tb)
  File "c:\users\harry\documents\oddsonglory\odds-on-glory\venv\lib\site-packages\flask\_compat.py", line 39, in reraise
    raise value
  File "c:\users\harry\documents\oddsonglory\odds-on-glory\venv\lib\site-packages\flask\app.py", line 1950, in full_dispatch_request
    rv = self.dispatch_request()
  File "c:\users\harry\documents\oddsonglory\odds-on-glory\venv\lib\site-packages\flask\app.py", line 1936, in dispatch_request
    return self.view_functions[rule.endpoint](**req.view_args)
  File "C:\Users\Harry\Documents\OddsOnGlory\odds-on-glory\app\routes.py", line 303, in user
    return render_template('user.html', user=user, glads=glads.items, bonus=bonus,
  File "c:\users\harry\documents\oddsonglory\odds-on-glory\venv\lib\site-packages\flask\templating.py", line 137, in render_template
    return _render(
  File "c:\users\harry\documents\oddsonglory\odds-on-glory\venv\lib\site-packages\flask\templating.py", line 120, in _render
    rv = template.render(context)
  File "c:\users\harry\documents\oddsonglory\odds-on-glory\venv\lib\site-packages\jinja2\environment.py", line 1090, in render
    self.environment.handle_exception()
  File "c:\users\harry\documents\oddsonglory\odds-on-glory\venv\lib\site-packages\jinja2\environment.py", line 832, in handle_exception
    reraise(*rewrite_traceback_stack(source=source))
  File "c:\users\harry\documents\oddsonglory\odds-on-glory\venv\lib\site-packages\jinja2\_compat.py", line 28, in reraise
    raise value.with_traceback(tb)
  File "C:\Users\Harry\Documents\OddsOnGlory\odds-on-glory\app\templates\user.html", line 1, in top-level template code
    {% extends "base.html" %}
  File "C:\Users\Harry\Documents\OddsOnGlory\odds-on-glory\app\templates\base.html", line 84, in top-level template code
    <a href="{{ url_for(report_issue) }}">Report Issue</a>
  File "c:\users\harry\documents\oddsonglory\odds-on-glory\venv\lib\site-packages\flask\helpers.py", line 318, in url_for
    if endpoint[:1] == ".":
jinja2.exceptions.UndefinedError: 'report_issue' is undefined
2020-07-04 10:17:59,652 INFO: OddsOnGlory Game [in C:\Users\Harry\Documents\OddsOnGlory\odds-on-glory\app\__init__.py:76]
2020-07-04 10:18:18,909 ERROR: Exception on /report_issue [GET] [in c:\users\harry\documents\oddsonglory\odds-on-glory\venv\lib\site-packages\flask\app.py:1891]
Traceback (most recent call last):
  File "c:\users\harry\documents\oddsonglory\odds-on-glory\venv\lib\site-packages\flask\app.py", line 2447, in wsgi_app
    response = self.full_dispatch_request()
  File "c:\users\harry\documents\oddsonglory\odds-on-glory\venv\lib\site-packages\flask\app.py", line 1953, in full_dispatch_request
    return self.finalize_request(rv)
  File "c:\users\harry\documents\oddsonglory\odds-on-glory\venv\lib\site-packages\flask\app.py", line 1968, in finalize_request
    response = self.make_response(rv)
  File "c:\users\harry\documents\oddsonglory\odds-on-glory\venv\lib\site-packages\flask\app.py", line 2097, in make_response
    raise TypeError(
TypeError: The view function did not return a valid response. The function either returned None or ended without a return statement.
2020-07-04 10:19:37,100 INFO: OddsOnGlory Game [in C:\Users\Harry\Documents\OddsOnGlory\odds-on-glory\app\__init__.py:76]
2020-07-04 10:22:07,152 INFO: OddsOnGlory Game [in C:\Users\Harry\Documents\OddsOnGlory\odds-on-glory\app\__init__.py:76]
2020-07-04 10:25:38,561 INFO: OddsOnGlory Game [in C:\Users\Harry\Documents\OddsOnGlory\odds-on-glory\app\__init__.py:76]
2020-07-04 10:27:37,015 INFO: OddsOnGlory Game [in C:\Users\Harry\Documents\OddsOnGlory\odds-on-glory\app\__init__.py:76]
2020-07-04 11:01:07,678 INFO: OddsOnGlory Game [in C:\Users\Harry\Documents\OddsOnGlory\odds-on-glory\app\__init__.py:76]
2020-07-04 11:01:36,486 ERROR: Exception on /report_issue [POST] [in c:\users\harry\documents\oddsonglory\odds-on-glory\venv\lib\site-packages\flask\app.py:1891]
Traceback (most recent call last):
  File "c:\users\harry\documents\oddsonglory\odds-on-glory\venv\lib\site-packages\flask\app.py", line 2447, in wsgi_app
    response = self.full_dispatch_request()
  File "c:\users\harry\documents\oddsonglory\odds-on-glory\venv\lib\site-packages\flask\app.py", line 1952, in full_dispatch_request
    rv = self.handle_user_exception(e)
  File "c:\users\harry\documents\oddsonglory\odds-on-glory\venv\lib\site-packages\flask\app.py", line 1821, in handle_user_exception
    reraise(exc_type, exc_value, tb)
  File "c:\users\harry\documents\oddsonglory\odds-on-glory\venv\lib\site-packages\flask\_compat.py", line 39, in reraise
    raise value
  File "c:\users\harry\documents\oddsonglory\odds-on-glory\venv\lib\site-packages\flask\app.py", line 1950, in full_dispatch_request
    rv = self.dispatch_request()
  File "c:\users\harry\documents\oddsonglory\odds-on-glory\venv\lib\site-packages\flask\app.py", line 1936, in dispatch_request
    return self.view_functions[rule.endpoint](**req.view_args)
  File "C:\Users\Harry\Documents\OddsOnGlory\odds-on-glory\app\routes.py", line 333, in report_issue
    send_report_issue_email(user, form.description.data)
  File "C:\Users\Harry\Documents\OddsOnGlory\odds-on-glory\app\email.py", line 33, in send_report_issue_email
    recipients=['ADMINS'][1],
IndexError: list index out of range
2020-07-04 11:02:35,629 INFO: OddsOnGlory Game [in C:\Users\Harry\Documents\OddsOnGlory\odds-on-glory\app\__init__.py:76]
2020-07-04 11:02:54,070 INFO: OddsOnGlory Game [in C:\Users\Harry\Documents\OddsOnGlory\odds-on-glory\app\__init__.py:76]
2020-07-04 11:03:05,412 ERROR: Exception on /report_issue [POST] [in c:\users\harry\documents\oddsonglory\odds-on-glory\venv\lib\site-packages\flask\app.py:1891]
Traceback (most recent call last):
  File "c:\users\harry\documents\oddsonglory\odds-on-glory\venv\lib\site-packages\flask\app.py", line 2447, in wsgi_app
    response = self.full_dispatch_request()
  File "c:\users\harry\documents\oddsonglory\odds-on-glory\venv\lib\site-packages\flask\app.py", line 1952, in full_dispatch_request
    rv = self.handle_user_exception(e)
  File "c:\users\harry\documents\oddsonglory\odds-on-glory\venv\lib\site-packages\flask\app.py", line 1821, in handle_user_exception
    reraise(exc_type, exc_value, tb)
  File "c:\users\harry\documents\oddsonglory\odds-on-glory\venv\lib\site-packages\flask\_compat.py", line 39, in reraise
    raise value
  File "c:\users\harry\documents\oddsonglory\odds-on-glory\venv\lib\site-packages\flask\app.py", line 1950, in full_dispatch_request
    rv = self.dispatch_request()
  File "c:\users\harry\documents\oddsonglory\odds-on-glory\venv\lib\site-packages\flask\app.py", line 1936, in dispatch_request
    return self.view_functions[rule.endpoint](**req.view_args)
  File "C:\Users\Harry\Documents\OddsOnGlory\odds-on-glory\app\routes.py", line 333, in report_issue
    send_report_issue_email(user, form.description.data)
  File "C:\Users\Harry\Documents\OddsOnGlory\odds-on-glory\app\email.py", line 34, in send_report_issue_email
    recipients=['ADMINS'][1],
IndexError: list index out of range
2020-07-04 11:03:50,488 INFO: OddsOnGlory Game [in C:\Users\Harry\Documents\OddsOnGlory\odds-on-glory\app\__init__.py:76]
2020-07-04 11:04:07,937 ERROR: Exception on /report_issue [POST] [in c:\users\harry\documents\oddsonglory\odds-on-glory\venv\lib\site-packages\flask\app.py:1891]
Traceback (most recent call last):
  File "c:\users\harry\documents\oddsonglory\odds-on-glory\venv\lib\site-packages\flask\app.py", line 2447, in wsgi_app
    response = self.full_dispatch_request()
  File "c:\users\harry\documents\oddsonglory\odds-on-glory\venv\lib\site-packages\flask\app.py", line 1952, in full_dispatch_request
    rv = self.handle_user_exception(e)
  File "c:\users\harry\documents\oddsonglory\odds-on-glory\venv\lib\site-packages\flask\app.py", line 1821, in handle_user_exception
    reraise(exc_type, exc_value, tb)
  File "c:\users\harry\documents\oddsonglory\odds-on-glory\venv\lib\site-packages\flask\_compat.py", line 39, in reraise
    raise value
  File "c:\users\harry\documents\oddsonglory\odds-on-glory\venv\lib\site-packages\flask\app.py", line 1950, in full_dispatch_request
    rv = self.dispatch_request()
  File "c:\users\harry\documents\oddsonglory\odds-on-glory\venv\lib\site-packages\flask\app.py", line 1936, in dispatch_request
    return self.view_functions[rule.endpoint](**req.view_args)
  File "C:\Users\Harry\Documents\OddsOnGlory\odds-on-glory\app\routes.py", line 333, in report_issue
    send_report_issue_email(user, form.description.data)
  File "C:\Users\Harry\Documents\OddsOnGlory\odds-on-glory\app\email.py", line 35, in send_report_issue_email
    recipients=['ADMINS'][1],
IndexError: list index out of range
2020-07-04 11:04:40,776 INFO: OddsOnGlory Game [in C:\Users\Harry\Documents\OddsOnGlory\odds-on-glory\app\__init__.py:76]
2020-07-04 11:06:29,680 INFO: OddsOnGlory Game [in C:\Users\Harry\Documents\OddsOnGlory\odds-on-glory\app\__init__.py:76]
2020-07-04 11:10:07,915 INFO: OddsOnGlory Game [in C:\Users\Harry\Documents\OddsOnGlory\odds-on-glory\app\__init__.py:76]
2020-07-04 11:11:57,899 INFO: OddsOnGlory Game [in C:\Users\Harry\Documents\OddsOnGlory\odds-on-glory\app\__init__.py:76]
2020-07-04 11:16:08,073 INFO: OddsOnGlory Game [in C:\Users\Harry\Documents\OddsOnGlory\odds-on-glory\app\__init__.py:76]
