2020-07-05 09:31:46,928 INFO: OddsOnGlory Game [in C:\Users\Harry\Documents\OddsOnGlory\odds-on-glory\app\__init__.py:76]
2020-07-05 09:32:17,181 ERROR: Exception on /host_game [GET] [in c:\users\harry\documents\oddsonglory\odds-on-glory\venv\lib\site-packages\flask\app.py:1891]
Traceback (most recent call last):
  File "c:\users\harry\documents\oddsonglory\odds-on-glory\venv\lib\site-packages\flask\app.py", line 1950, in full_dispatch_request
    rv = self.dispatch_request()
  File "c:\users\harry\documents\oddsonglory\odds-on-glory\venv\lib\site-packages\flask\app.py", line 1926, in dispatch_request
    self.raise_routing_exception(req)
  File "c:\users\harry\documents\oddsonglory\odds-on-glory\venv\lib\site-packages\flask\app.py", line 1908, in raise_routing_exception
    raise request.routing_exception
  File "c:\users\harry\documents\oddsonglory\odds-on-glory\venv\lib\site-packages\flask\ctx.py", line 350, in match_request
    result = self.url_adapter.match(return_rule=True)
  File "c:\users\harry\documents\oddsonglory\odds-on-glory\venv\lib\site-packages\werkzeug\routing.py", line 1945, in match
    raise NotFound()
werkzeug.exceptions.NotFound: 404 Not Found: The requested URL was not found on the server. If you entered the URL manually please check your spelling and try again.

During handling of the above exception, another exception occurred:

Traceback (most recent call last):
  File "c:\users\harry\documents\oddsonglory\odds-on-glory\venv\lib\site-packages\sqlalchemy\engine\base.py", line 1283, in _execute_context
    self.dialect.do_execute(
  File "c:\users\harry\documents\oddsonglory\odds-on-glory\venv\lib\site-packages\sqlalchemy\engine\default.py", line 590, in do_execute
    cursor.execute(statement, parameters)
sqlite3.OperationalError: no such table: user

The above exception was the direct cause of the following exception:

Traceback (most recent call last):
  File "c:\users\harry\documents\oddsonglory\odds-on-glory\venv\lib\site-packages\flask\app.py", line 2447, in wsgi_app
    response = self.full_dispatch_request()
  File "c:\users\harry\documents\oddsonglory\odds-on-glory\venv\lib\site-packages\flask\app.py", line 1952, in full_dispatch_request
    rv = self.handle_user_exception(e)
  File "c:\users\harry\documents\oddsonglory\odds-on-glory\venv\lib\site-packages\flask\app.py", line 1816, in handle_user_exception
    return self.handle_http_exception(e)
  File "c:\users\harry\documents\oddsonglory\odds-on-glory\venv\lib\site-packages\flask\app.py", line 1744, in handle_http_exception
    return handler(e)
  File "C:\Users\Harry\Documents\OddsOnGlory\odds-on-glory\app\errors.py", line 6, in not_found_error
    return render_template('404.html'), 404
  File "c:\users\harry\documents\oddsonglory\odds-on-glory\venv\lib\site-packages\flask\templating.py", line 136, in render_template
    ctx.app.update_template_context(context)
  File "c:\users\harry\documents\oddsonglory\odds-on-glory\venv\lib\site-packages\flask\app.py", line 838, in update_template_context
    context.update(func())
  File "c:\users\harry\documents\oddsonglory\odds-on-glory\venv\lib\site-packages\flask_login\utils.py", line 379, in _user_context_processor
    return dict(current_user=_get_user())
  File "c:\users\harry\documents\oddsonglory\odds-on-glory\venv\lib\site-packages\flask_login\utils.py", line 346, in _get_user
    current_app.login_manager._load_user()
  File "c:\users\harry\documents\oddsonglory\odds-on-glory\venv\lib\site-packages\flask_login\login_manager.py", line 318, in _load_user
    user = self._user_callback(user_id)
  File "C:\Users\Harry\Documents\OddsOnGlory\odds-on-glory\app\models.py", line 12, in load_user
    return User.query.get(int(id))
  File "c:\users\harry\documents\oddsonglory\odds-on-glory\venv\lib\site-packages\sqlalchemy\orm\query.py", line 1021, in get
    return self._get_impl(ident, loading.load_on_pk_identity)
  File "c:\users\harry\documents\oddsonglory\odds-on-glory\venv\lib\site-packages\sqlalchemy\orm\query.py", line 1138, in _get_impl
    return db_load_fn(self, primary_key_identity)
  File "c:\users\harry\documents\oddsonglory\odds-on-glory\venv\lib\site-packages\sqlalchemy\orm\loading.py", line 287, in load_on_pk_identity
    return q.one()
  File "c:\users\harry\documents\oddsonglory\odds-on-glory\venv\lib\site-packages\sqlalchemy\orm\query.py", line 3436, in one
    ret = self.one_or_none()
  File "c:\users\harry\documents\oddsonglory\odds-on-glory\venv\lib\site-packages\sqlalchemy\orm\query.py", line 3405, in one_or_none
    ret = list(self)
  File "c:\users\harry\documents\oddsonglory\odds-on-glory\venv\lib\site-packages\sqlalchemy\orm\query.py", line 3481, in __iter__
    return self._execute_and_instances(context)
  File "c:\users\harry\documents\oddsonglory\odds-on-glory\venv\lib\site-packages\sqlalchemy\orm\query.py", line 3506, in _execute_and_instances
    result = conn.execute(querycontext.statement, self._params)
  File "c:\users\harry\documents\oddsonglory\odds-on-glory\venv\lib\site-packages\sqlalchemy\engine\base.py", line 1020, in execute
    return meth(self, multiparams, params)
  File "c:\users\harry\documents\oddsonglory\odds-on-glory\venv\lib\site-packages\sqlalchemy\sql\elements.py", line 298, in _execute_on_connection
    return connection._execute_clauseelement(self, multiparams, params)
  File "c:\users\harry\documents\oddsonglory\odds-on-glory\venv\lib\site-packages\sqlalchemy\engine\base.py", line 1133, in _execute_clauseelement
    ret = self._execute_context(
  File "c:\users\harry\documents\oddsonglory\odds-on-glory\venv\lib\site-packages\sqlalchemy\engine\base.py", line 1323, in _execute_context
    self._handle_dbapi_exception(
  File "c:\users\harry\documents\oddsonglory\odds-on-glory\venv\lib\site-packages\sqlalchemy\engine\base.py", line 1517, in _handle_dbapi_exception
    util.raise_(
  File "c:\users\harry\documents\oddsonglory\odds-on-glory\venv\lib\site-packages\sqlalchemy\util\compat.py", line 178, in raise_
    raise exception
  File "c:\users\harry\documents\oddsonglory\odds-on-glory\venv\lib\site-packages\sqlalchemy\engine\base.py", line 1283, in _execute_context
    self.dialect.do_execute(
  File "c:\users\harry\documents\oddsonglory\odds-on-glory\venv\lib\site-packages\sqlalchemy\engine\default.py", line 590, in do_execute
    cursor.execute(statement, parameters)
sqlalchemy.exc.OperationalError: (sqlite3.OperationalError) no such table: user
[SQL: SELECT user.id AS user_id, user.username AS user_username, user.email AS user_email, user.password_hash AS user_password_hash, user.money AS user_money, user.money_rank AS user_money_rank, user.last_bonus AS user_last_bonus 
FROM user 
WHERE user.id = ?]
[parameters: (17,)]
(Background on this error at: http://sqlalche.me/e/e3q8)
