2020-06-17 08:29:00,609 INFO: OddsOnGlory Game [in C:\Users\Harry\Documents\OddsOnGlory\odds-on-glory\app\__init__.py:52]
2020-06-17 08:30:19,644 INFO: OddsOnGlory Game [in C:\Users\Harry\Documents\OddsOnGlory\odds-on-glory\app\__init__.py:52]
2020-06-17 08:30:48,957 INFO: OddsOnGlory Game [in C:\Users\Harry\Documents\OddsOnGlory\odds-on-glory\app\__init__.py:52]
2020-06-17 08:31:58,687 INFO: OddsOnGlory Game [in C:\Users\Harry\Documents\OddsOnGlory\odds-on-glory\app\__init__.py:52]
2020-06-17 08:32:43,039 INFO: OddsOnGlory Game [in C:\Users\Harry\Documents\OddsOnGlory\odds-on-glory\app\__init__.py:52]
2020-06-17 08:33:30,841 ERROR: Exception on /finish_game [POST] [in C:\Users\Harry\Documents\OddsOnGlory\odds-on-glory\venv\lib\site-packages\flask\app.py:1891]
Traceback (most recent call last):
  File "C:\Users\Harry\Documents\OddsOnGlory\odds-on-glory\venv\lib\site-packages\flask\app.py", line 2447, in wsgi_app
    response = self.full_dispatch_request()
  File "C:\Users\Harry\Documents\OddsOnGlory\odds-on-glory\venv\lib\site-packages\flask\app.py", line 1952, in full_dispatch_request
    rv = self.handle_user_exception(e)
  File "C:\Users\Harry\Documents\OddsOnGlory\odds-on-glory\venv\lib\site-packages\flask\app.py", line 1821, in handle_user_exception
    reraise(exc_type, exc_value, tb)
  File "C:\Users\Harry\Documents\OddsOnGlory\odds-on-glory\venv\lib\site-packages\flask\_compat.py", line 39, in reraise
    raise value
  File "C:\Users\Harry\Documents\OddsOnGlory\odds-on-glory\venv\lib\site-packages\flask\app.py", line 1950, in full_dispatch_request
    rv = self.dispatch_request()
  File "C:\Users\Harry\Documents\OddsOnGlory\odds-on-glory\venv\lib\site-packages\flask\app.py", line 1936, in dispatch_request
    return self.view_functions[rule.endpoint](**req.view_args)
  File "C:\Users\Harry\Documents\OddsOnGlory\odds-on-glory\app\routes.py", line 106, in finish_game
    game = Tournament.query.filter_by(id=game.id).first_or_404()
AttributeError: 'GameHandler' object has no attribute 'id'
2020-06-17 08:34:11,781 INFO: OddsOnGlory Game [in C:\Users\Harry\Documents\OddsOnGlory\odds-on-glory\app\__init__.py:52]
2020-06-17 08:34:51,236 ERROR: Exception on /finish_game [POST] [in C:\Users\Harry\Documents\OddsOnGlory\odds-on-glory\venv\lib\site-packages\flask\app.py:1891]
Traceback (most recent call last):
  File "C:\Users\Harry\Documents\OddsOnGlory\odds-on-glory\venv\lib\site-packages\flask\app.py", line 2447, in wsgi_app
    response = self.full_dispatch_request()
  File "C:\Users\Harry\Documents\OddsOnGlory\odds-on-glory\venv\lib\site-packages\flask\app.py", line 1952, in full_dispatch_request
    rv = self.handle_user_exception(e)
  File "C:\Users\Harry\Documents\OddsOnGlory\odds-on-glory\venv\lib\site-packages\flask\app.py", line 1821, in handle_user_exception
    reraise(exc_type, exc_value, tb)
  File "C:\Users\Harry\Documents\OddsOnGlory\odds-on-glory\venv\lib\site-packages\flask\_compat.py", line 39, in reraise
    raise value
  File "C:\Users\Harry\Documents\OddsOnGlory\odds-on-glory\venv\lib\site-packages\flask\app.py", line 1950, in full_dispatch_request
    rv = self.dispatch_request()
  File "C:\Users\Harry\Documents\OddsOnGlory\odds-on-glory\venv\lib\site-packages\flask\app.py", line 1936, in dispatch_request
    return self.view_functions[rule.endpoint](**req.view_args)
  File "C:\Users\Harry\Documents\OddsOnGlory\odds-on-glory\app\routes.py", line 106, in finish_game
    game = Tournament.query.filter_by(id=game.id).first_or_404()
AttributeError: 'GameHandler' object has no attribute 'id'
2020-06-17 08:36:36,891 INFO: OddsOnGlory Game [in C:\Users\Harry\Documents\OddsOnGlory\odds-on-glory\app\__init__.py:52]
2020-06-17 08:37:23,181 ERROR: Exception on /finish_game [POST] [in C:\Users\Harry\Documents\OddsOnGlory\odds-on-glory\venv\lib\site-packages\flask\app.py:1891]
Traceback (most recent call last):
  File "C:\Users\Harry\Documents\OddsOnGlory\odds-on-glory\venv\lib\site-packages\flask\app.py", line 2447, in wsgi_app
    response = self.full_dispatch_request()
  File "C:\Users\Harry\Documents\OddsOnGlory\odds-on-glory\venv\lib\site-packages\flask\app.py", line 1952, in full_dispatch_request
    rv = self.handle_user_exception(e)
  File "C:\Users\Harry\Documents\OddsOnGlory\odds-on-glory\venv\lib\site-packages\flask\app.py", line 1821, in handle_user_exception
    reraise(exc_type, exc_value, tb)
  File "C:\Users\Harry\Documents\OddsOnGlory\odds-on-glory\venv\lib\site-packages\flask\_compat.py", line 39, in reraise
    raise value
  File "C:\Users\Harry\Documents\OddsOnGlory\odds-on-glory\venv\lib\site-packages\flask\app.py", line 1950, in full_dispatch_request
    rv = self.dispatch_request()
  File "C:\Users\Harry\Documents\OddsOnGlory\odds-on-glory\venv\lib\site-packages\flask\app.py", line 1936, in dispatch_request
    return self.view_functions[rule.endpoint](**req.view_args)
  File "C:\Users\Harry\Documents\OddsOnGlory\odds-on-glory\app\routes.py", line 106, in finish_game
    game = Tournament.query.filter_by(id=game_id).first_or_404()
NameError: name 'game_id' is not defined
2020-06-17 08:37:35,734 INFO: OddsOnGlory Game [in C:\Users\Harry\Documents\OddsOnGlory\odds-on-glory\app\__init__.py:52]
