2020-06-06 10:59:52,552 INFO: OddsOnGlory Game [in C:\Users\Harry\Documents\OddsOnGlory\odds-on-glory\app\__init__.py:42
2020-06-06 11:00:06,361 INFO: OddsOnGlory Game [in C:\Users\Harry\Documents\OddsOnGlory\odds-on-glory\app\__init__.py:42
2020-06-06 11:00:17,066 ERROR: Exception on /edit_profile [POST] [in c:\users\harry\appdata\local\programs\python\python37\lib\site-packages\flask\app.py:1892
Traceback (most recent call last):
  File "c:\users\harry\appdata\local\programs\python\python37\lib\site-packages\sqlalchemy\engine\base.py", line 1284, in _execute_context
    cursor, statement, parameters, context
  File "c:\users\harry\appdata\local\programs\python\python37\lib\site-packages\sqlalchemy\engine\default.py", line 590, in do_execute
    cursor.execute(statement, parameters)
sqlite3.IntegrityError: UNIQUE constraint failed: user.username

The above exception was the direct cause of the following exception:

Traceback (most recent call last):
  File "c:\users\harry\appdata\local\programs\python\python37\lib\site-packages\flask\app.py", line 2447, in wsgi_app
    response = self.full_dispatch_request()
  File "c:\users\harry\appdata\local\programs\python\python37\lib\site-packages\flask\app.py", line 1952, in full_dispatch_request
    rv = self.handle_user_exception(e)
  File "c:\users\harry\appdata\local\programs\python\python37\lib\site-packages\flask\app.py", line 1821, in handle_user_exception
    reraise(exc_type, exc_value, tb)
  File "c:\users\harry\appdata\local\programs\python\python37\lib\site-packages\flask\_compat.py", line 39, in reraise
    raise value
  File "c:\users\harry\appdata\local\programs\python\python37\lib\site-packages\flask\app.py", line 1950, in full_dispatch_request
    rv = self.dispatch_request()
  File "c:\users\harry\appdata\local\programs\python\python37\lib\site-packages\flask\app.py", line 1936, in dispatch_request
    return self.view_functions[rule.endpoint](**req.view_args)
  File "c:\users\harry\appdata\local\programs\python\python37\lib\site-packages\flask_login\utils.py", line 272, in decorated_view
    return func(*args, **kwargs)
  File "C:\Users\Harry\Documents\OddsOnGlory\odds-on-glory\app\routes.py", line 91, in edit_profile
    db.session.commit()
  File "c:\users\harry\appdata\local\programs\python\python37\lib\site-packages\sqlalchemy\orm\scoping.py", line 163, in do
    return getattr(self.registry(), name)(*args, **kwargs)
  File "c:\users\harry\appdata\local\programs\python\python37\lib\site-packages\sqlalchemy\orm\session.py", line 1042, in commit
    self.transaction.commit()
  File "c:\users\harry\appdata\local\programs\python\python37\lib\site-packages\sqlalchemy\orm\session.py", line 504, in commit
    self._prepare_impl()
  File "c:\users\harry\appdata\local\programs\python\python37\lib\site-packages\sqlalchemy\orm\session.py", line 483, in _prepare_impl
    self.session.flush()
  File "c:\users\harry\appdata\local\programs\python\python37\lib\site-packages\sqlalchemy\orm\session.py", line 2523, in flush
    self._flush(objects)
  File "c:\users\harry\appdata\local\programs\python\python37\lib\site-packages\sqlalchemy\orm\session.py", line 2664, in _flush
    transaction.rollback(_capture_exception=True)
  File "c:\users\harry\appdata\local\programs\python\python37\lib\site-packages\sqlalchemy\util\langhelpers.py", line 69, in __exit__
    exc_value, with_traceback=exc_tb,
  File "c:\users\harry\appdata\local\programs\python\python37\lib\site-packages\sqlalchemy\util\compat.py", line 178, in raise_
    raise exception
  File "c:\users\harry\appdata\local\programs\python\python37\lib\site-packages\sqlalchemy\orm\session.py", line 2624, in _flush
    flush_context.execute()
  File "c:\users\harry\appdata\local\programs\python\python37\lib\site-packages\sqlalchemy\orm\unitofwork.py", line 422, in execute
    rec.execute(self)
  File "c:\users\harry\appdata\local\programs\python\python37\lib\site-packages\sqlalchemy\orm\unitofwork.py", line 589, in execute
    uow,
  File "c:\users\harry\appdata\local\programs\python\python37\lib\site-packages\sqlalchemy\orm\persistence.py", line 236, in save_obj
    update,
  File "c:\users\harry\appdata\local\programs\python\python37\lib\site-packages\sqlalchemy\orm\persistence.py", line 995, in _emit_update_statements
    statement, multiparams
  File "c:\users\harry\appdata\local\programs\python\python37\lib\site-packages\sqlalchemy\engine\base.py", line 1020, in execute
    return meth(self, multiparams, params)
  File "c:\users\harry\appdata\local\programs\python\python37\lib\site-packages\sqlalchemy\sql\elements.py", line 298, in _execute_on_connection
    return connection._execute_clauseelement(self, multiparams, params)
  File "c:\users\harry\appdata\local\programs\python\python37\lib\site-packages\sqlalchemy\engine\base.py", line 1139, in _execute_clauseelement
    distilled_params,
  File "c:\users\harry\appdata\local\programs\python\python37\lib\site-packages\sqlalchemy\engine\base.py", line 1324, in _execute_context
    e, statement, parameters, cursor, context
  File "c:\users\harry\appdata\local\programs\python\python37\lib\site-packages\sqlalchemy\engine\base.py", line 1518, in _handle_dbapi_exception
    sqlalchemy_exception, with_traceback=exc_info[2], from_=e
  File "c:\users\harry\appdata\local\programs\python\python37\lib\site-packages\sqlalchemy\util\compat.py", line 178, in raise_
    raise exception
  File "c:\users\harry\appdata\local\programs\python\python37\lib\site-packages\sqlalchemy\engine\base.py", line 1284, in _execute_context
    cursor, statement, parameters, context
  File "c:\users\harry\appdata\local\programs\python\python37\lib\site-packages\sqlalchemy\engine\default.py", line 590, in do_execute
    cursor.execute(statement, parameters)
sqlalchemy.exc.IntegrityError: (sqlite3.IntegrityError) UNIQUE constraint failed: user.username
[SQL: UPDATE user SET username=?, about_me=? WHERE user.id = ?]
[parameters: ('katie', 'My name is yellow', 3)]
(Background on this error at: http://sqlalche.me/e/gkpj)
2020-06-06 11:08:00,045 INFO: OddsOnGlory Game [in C:\Users\Harry\Documents\OddsOnGlory\odds-on-glory\app\__init__.py:42
